Workbook

Sheet SUMMARY
A3: MIGRANT WORKERS PROCESSING DIVISION
A4: SUMMARY OF JOBS FAIR FACILITATED/ SUPERVISED REPORT
A5: FY 2025
A7: MONTHS | B7: NO. OF JOBS FAIR FACILITATED/ SUPERVISED | C7: NUMBER OF REGISTERED APPLICANTS | F7: NUMBER OF PARTICIPATING AGENCIES
C8: MALE | D8: FEMALE | E8: TOTAL: | F8: LAND BASED RECRUITMENT AGENCY | G8: SEA-BASED/ MANNING AGENCY
A9: JANUARY | B9: =JAN!E18 -> 1 | C9: =JAN!F18 -> 25 | D9: =JAN!G18 -> 20 | E9: =SUM(C9:D9) -> 45 | F9: =JAN!I18 -> 2 | G9: =JAN!J18 -> 0
A10: FEBRUARY | B10: =FEB!E19 -> 1 | C10: =FEB!F19 -> 16 | D10: =FEB!G19 -> 6 | E10: =SUM(C10:D10) -> 22 | F10: =FEB!I19 -> 3 | G10: =FEB!J19 -> 0
A11: MARCH | B11: =MAR!E20 -> 2 | C11: =MAR!F20 -> 20 | D11: =MAR!G20 -> 17 | E11: =SUM(C11:D11) -> 37 | F11: =MAR!I20 -> 3 | G11: =MAR!J20 -> 0
A12: APRIL | B12: =APR!E24 -> 3 | C12: =APR!F24 -> 26 | D12: =APR!G24 -> 72 | E12: =SUM(C12:D12) -> 98 | F12: =APR!I24 -> 6 | G12: =APR!J24 -> 0
A13: MAY | B13: =MAY!E39 -> 6 | C13: =MAY!F39 -> 173 | D13: =MAY!G39 -> 189 | E13: =SUM(C13:D13) -> 362 | F13: =MAY!I39 -> 18 | G13: =MAY!J39 -> 0
A14: JUNE | B14: =JUNE!E49 -> 9 | C14: =JUNE!F49 -> 188 | D14: =JUNE!G49 -> 205 | E14: =SUM(C14:D14) -> 393 | F14: =JUNE!I49 -> 25 | G14: =JUNE!J49 -> 0
A15: SUB TOTAL: | B15: =SUM(B9:B14) -> 22 | C15: =SUM(C9:C14) -> 448 | D15: =SUM(D9:D14) -> 509 | E15: =SUM(E9:E14) -> 957 | F15: =SUM(F9:F14) -> 57 | G15: =SUM(G9:G14) -> 0
A16: JULY | B16: =JULY!E28 -> 4 | C16: =JULY!F28 -> 66 | D16: =JULY!G28 -> 46 | E16: =SUM(C16:D16) -> 112 | F16: =JULY!I28 -> 9 | G16: =JULY!J28 -> 0
A17: AUGUST | B17: =AUG!E35 -> 4 | C17: =AUG!F35 -> 90 | D17: =AUG!G35 -> 135 | E17: =SUM(C17:D17) -> 225 | F17: =AUG!I35 -> 16 | G17: =AUG!J35 -> 0
A18: SEPTEMBER | B18: =SEP!E58 -> 11 | C18: =SEP!F58 -> 438 | D18: =SEP!G58 -> 293 | E18: =SUM(C18:D18) -> 731 | F18: =SEP!I58 -> 32 | G18: =SEP!J58 -> 0
A19: OCTOBER | B19: =OCT!E20 -> 2 | C19: =OCT!F20 -> 8 | D19: =OCT!G20 -> 11 | E19: =SUM(C19:D19) -> 19 | F19: =OCT!I20 -> 3 | G19: =OCT!J20 -> 0
A20: NOVEMBER | B20: =NOV!E20 -> 1 | C20: =NOV!F20 -> 39 | D20: =NOV!G20 -> 25 | E20: =SUM(C20:D20) -> 64 | F20: =NOV!I20 -> 4 | G20: =NOV!J20 -> 0
A21: DECEMBER | B21: =DEC!$E$22 -> 2 | C21: =DEC!$F$22 -> 19 | D21: =DEC!$G$22 -> 25 | E21: =SUM(C21:D21) -> 44 | F21: =DEC!$I$22 -> 5 | G21: =DEC!$J$22 -> 0
A22: SUB TOTAL: | B22: =SUM(B16:B21) -> 24 | C22: =SUM(C16:C21) -> 660 | D22: =SUM(D16:D21) -> 535 | E22: =SUM(E16:E21) -> 1195 | F22: =SUM(F16:F21) -> 69 | G22: =SUM(G16:G21) -> 0
A23: TOTAL: | B23: =B15+B22 -> 46 | C23: =C15+C22 -> 1108 | D23: =D15+D22 -> 1044 | E23: =E15+E22 -> 2152 | F23: =F15+F22 -> 126 | G23: =G15+G22 -> 0
A25: Prepared by: | E25: Noted by:
A29: AURORA JEAN A. TORRALBA | E29: REGIENALD S. ESPALDON, CPA
A30: Labor and Employment Officer I | E30: Chief Administrative Officer and
E31: OIC-Assistant Regional Director
E33: Approved by:
E37: RITCHEL M. BUTAO
E38: OIC-Regional Director
A42: EP / IJEP / MAG

Sheet JAN
A10: JOB FAIR REPORT
A11: FOR THE MONTH OF JANUARY 2025
A13: AGENCY/ INSTITUTION | B13: JOB FAIR DATES | C13: JOB FAIR VENUE | D13: AGENCY | E13: NO. OF JOBS FAIR FACILITATED/ SUPERVISED | F13: NUMBER OF REGISTERED APPLICANTS | I13: NUMBER OF PARTICIPATING AGENCIES
F14: MALE | G14: FEMALE | H14: TOTAL: | I14: LAND BASED RECRUITMENT AGENCY | J14: SEA-BASED/ MANNING AGENCY | K14: TOTAL:
A15: LGU-CABADBARAN CITY | B15: 45688 | C15: Robinsons Place, Butuan City | D15: JENERICK INTERNATIONAL MANPOWER INC. | E15: 1 | F15: =7+6 -> 13 | G15: =3+4 -> 7 | H15: =F15+G15 -> 20 | I15: 1 | K15: =I15+J15 -> 1
D16: MMML RECRUITMENT SERVICES INC. | F16: =5+7 -> 12 | G16: =5+3+5 -> 13 | H16: =F16+G16 -> 25 | I16: 1 | K16: =I16+J16 -> 1
A17: Sub total: | E17: =SUM(E15:E16) -> 1 | F17: =SUM(F15:F16) -> 25 | G17: =SUM(G15:G16) -> 20 | H17: =SUM(H15:H16) -> 45 | I17: =SUM(I15:I16) -> 2 | J17: =SUM(J15:J16) -> 0 | K17: =SUM(K15:K16) -> 2
A18: GRAND TOTAL: | E18: =E17 -> 1 | F18: =F17 -> 25 | G18: =G17 -> 20 | H18: =H17 -> 45 | I18: =I17 -> 2 | J18: =J17 -> 0 | K18: =K17 -> 2
A20: Prepared by: | E20: Noted by:
A24: AURORA JEAN A. TORRALBA | E24: EDDIE PARAGUYA
A25: Labor and Employment Officer I | E25: Senior Labor and Employment Officer

Sheet FEB
A10: JOB FAIR REPORT
A11: FOR THE MONTH OF FEBRUARY 2025
A13: AGENCY/ INSTITUTION | B13: JOB FAIR DATES | C13: JOB FAIR VENUE | D13: AGENCY | E13: NO. OF JOBS FAIR FACILITATED/ SUPERVISED | F13: NUMBER OF REGISTERED APPLICANTS | I13: NUMBER OF PARTICIPATING AGENCIES
F14: MALE | G14: FEMALE | H14: TOTAL: | I14: LAND BASED RECRUITMENT AGENCY | J14: SEA-BASED/ MANNING AGENCY | K14: TOTAL:
A15: MUNICIPALITY OF SAN JOSE, DINAGAT ISLAND | B15: 45708 | C15: CITY SOCIAL HALL, PEOPLES GOVERNMENT CENTER, CABADBARAN CITY | D15: NANSEI TEIKOKU GLOBAL PLACEMENT SERVICES INC. | E15: 1 | F15: 5 | G15: 3 | H15: =F15+G15 -> 8 | I15: 1 | K15: =I15+J15 -> 1
D16: EAST WEST PLACEMENT CENTER INC. | F16: 2 | G16: 1 | H16: =F16+G16 -> 3 | I16: 1 | K16: =I16+J16 -> 1
D17: JENERICK INTERNATIONAL MANPOWER INC. | F17: 9 | G17: 2 | H17: =F17+G17 -> 11 | I17: 1 | K17: =I17+J17 -> 1
A18: Sub total: | E18: =SUM(E15:E17) -> 1 | F18: =SUM(F15:F17) -> 16 | G18: =SUM(G15:G17) -> 6 | H18: =SUM(H15:H17) -> 22 | I18: =SUM(I15:I17) -> 3 | J18: =SUM(J15:J17) -> 0 | K18: =SUM(K15:K17) -> 3
A19: GRAND TOTAL: | E19: =E18 -> 1 | F19: =F18 -> 16 | G19: =G18 -> 6 | H19: =H18 -> 22 | I19: =I18 -> 3 | J19: =J18 -> 0 | K19: =K18 -> 3
A21: Prepared by: | E21: Noted by:
A25: AURORA JEAN A. TORRALBA | E25: EDDIE PARAGUYA
A26: Labor and Employment Officer I | E26: Senior Labor and Employment Officer

Sheet MAR
A10: JOB FAIR REPORT
A11: FOR THE MONTH OF MARCH 2025
A13: AGENCY/ INSTITUTION | B13: JOB FAIR DATES | C13: JOB FAIR VENUE | D13: AGENCY | E13: NO. OF JOBS FAIR FACILITATED/ SUPERVISED | F13: NUMBER OF REGISTERED APPLICANTS | I13: NUMBER OF PARTICIPATING AGENCIES
F14: MALE | G14: FEMALE | H14: TOTAL: | I14: LAND BASED RECRUITMENT AGENCY | J14: SEA-BASED/ MANNING AGENCY | K14: TOTAL:
A15: MUNICIPALITY OF SAN JOSE, DINAGAT ISLAND | B15: March 13-14, 2025 | C15: Municipal Covered Court, Brgy. Sta. Cruz, San Jose, Province of Dinagat Island | D15: STARWORLD INTERNATIONAL MANPOWER & PLACEMENT AGENCY INC. | E15: 1 | F15: 9 | G15: 8 | H15: =F15+G15 -> 17 | I15: 1 | K15: =I15+J15 -> 1
D16: PLACEWELL INTERNATIONAL SERVICES CORPORATION | F16: 9 | G16: 8 | H16: =F16+G16 -> 17 | I16: 1 | K16: =I16+J16 -> 1
A17: Sub total: | E17: =SUM(E15:E16) -> 1 | F17: =SUM(F15:F16) -> 18 | G17: =SUM(G15:G16) -> 16 | H17: =SUM(H15:H16) -> 34 | I17: =SUM(I15:I16) -> 2 | J17: =SUM(J15:J16) -> 0 | K17: =SUM(K15:K16) -> 2
A18: MUNICIPALITY OF CAGDIANAO, DINAGAT ISLAND | B18: MARCH 27-28, 2025 | C18: Cagdianao Cultural and Sports Center, Cagdianao, Province of Dinagat Islands | D18: PLACEWELL INTERNATIONAL SERVICES CORPORATION | E18: 1 | F18: 2 | G18: 1 | H18: =F18+G18 -> 3 | I18: 1 | K18: =I18+J18 -> 1
A19: Sub total: | E19: =E18 -> 1 | F19: =F18 -> 2 | G19: =G18 -> 1 | H19: =H18 -> 3 | I19: =I18 -> 1 | J19: =J18 -> 0 | K19: =K18 -> 1
A20: GRAND TOTAL: | E20: =E17+E19 -> 2 | F20: =F17+F19 -> 20 | G20: =G17+G19 -> 17 | H20: =H17+H19 -> 37 | I20: =I17+I19 -> 3 | J20: =J17+J19 -> 0 | K20: =K17+K19 -> 3
A22: Prepared by: | E22: Noted by:
A26: AURORA JEAN A. TORRALBA | E26: EDDIE PARAGUYA
A27: Labor and Employment Officer I | E27: Senior Labor and Employment Officer

Sheet APR
A10: JOB FAIR REPORT
A11: FOR THE MONTH OF APRIL 2025
A13: ORGANIZER | B13: JOB FAIR DATES | C13: JOB FAIR VENUE | D13: AGENCY | E13: NO. OF JOBS FAIR FACILITATED/ SUPERVISED | F13: NUMBER OF REGISTERED APPLICANTS | I13: NUMBER OF PARTICIPATING AGENCIES
F14: MALE | G14: FEMALE | H14: TOTAL: | I14: LAND BASED RECRUITMENT AGENCY | J14: SEA-BASED/ MANNING AGENCY | K14: TOTAL:
A15: DOLE- AGUSAN DEL SUR AND PESO SAN LUIS | B15: 45756 | C15: Amphi Theater, Doña Maxima, San Luis, Agusan del Sur | D15: PLACEWELL INTERNATIONAL SERVICES CORPORATION | E15: 1 | G15: 3 | H15: =F15+G15 -> 3 | I15: 1 | K15: =I15+J15 -> 1
D16: JENERICK INTERNATIONAL MANPOWER INC. | F16: 2 | G16: 1 | H16: =F16+G16 -> 3 | I16: 1 | K16: =I16+J16 -> 1
A17: Sub total: | E17: =SUM(E15:E16) -> 1 | F17: =SUM(F15:F16) -> 2 | G17: =SUM(G15:G16) -> 4 | H17: =SUM(H15:H16) -> 6 | I17: =SUM(I15:I16) -> 2 | J17: =SUM(J15:J16) -> 0 | K17: =SUM(K15:K16) -> 2
A18: SAINT MICHAEL COLLEGE OF CARAGA | B18: 45758 | C18: SMCC Quadrangle, Nasipit Agusan del Norte | D18: PLACEWELL INTERNATIONAL SERVICES CORPORATION | E18: 1 | F18: =4+1 -> 5 | G18: =6+9+3 -> 18 | H18: =F18+G18 -> 23 | I18: 1 | K18: =I18+J18 -> 1
D19: EAST WEST PLACEMENT CENTER INC. | F19: 4 | G19: =8+6+7 -> 21 | H19: =F19+G19 -> 25 | I19: 1 | K19: =I19+J19 -> 1
A20: Sub total: | E20: =SUM(E18:E19) -> 1 | F20: =SUM(F18:F19) -> 9 | G20: =SUM(G18:G19) -> 39 | H20: =SUM(H18:H19) -> 48 | I20: =SUM(I18:I19) -> 2 | J20: =SUM(J18:J19) -> 0 | K20: =SUM(K18:K19) -> 2
A21: CARAGA STATE UNIVERSITY CABADBARAN CAMPUS (CSUCC) | B21: 45771 | C21: CSUCC Gymnasium, Cabadbaran City | D21: PLACEWELL INTERNATIONAL SERVICES CORPORATION | E21: 1 | F21: =4+3+7 -> 14 | G21: =6+7+3+4 -> 20 | H21: =F21+G21 -> 34 | I21: 1 | K21: =I21+J21 -> 1
D22: JENERICK INTERNATIONAL MANPOWER INC. | F22: 1 | G22: 9 | H22: =F22+G22 -> 10 | I22: 1 | K22: =I22+J22 -> 1
A23: Sub total: | E23: =E21 -> 1 | F23: =SUM(F21:F22) -> 15 | G23: =SUM(G21:G22) -> 29 | H23: =SUM(H21:H22) -> 44 | I23: =SUM(I21:I22) -> 2 | J23: =SUM(J21:J22) -> 0 | K23: =SUM(K21:K22) -> 2
A24: GRAND TOTAL: | E24: =E17+E20+E23 -> 3 | F24: =F23+F20+F17 -> 26 | G24: =G23+G20+G17 -> 72 | H24: =H23+H20+H17 -> 98 | I24: =I17+I20+I23 -> 6 | J24: =J17+J20+J23 -> 0 | K24: =K17+K20+K23 -> 6
A26: Prepared by: | E26: Noted by:
A30: AURORA JEAN A. TORRALBA | E30: EDDIE PARAGUYA
A31: Labor and Employment Officer I | E31: Senior Labor and Employment Officer

Sheet MAY
A10: JOB FAIR REPORT
A11: FOR THE MONTH OF MAY 2025
A13: ORGANIZER | B13: JOB FAIR DATES | C13: JOB FAIR VENUE | D13: AGENCY | E13: NO. OF JOBS FAIR FACILITATED/ SUPERVISED | F13: NUMBER OF REGISTERED APPLICANTS | I13: NUMBER OF PARTICIPATING AGENCIES
F14: MALE | G14: FEMALE | H14: TOTAL: | I14: LAND BASED RECRUITMENT AGENCY | J14: SEA-BASED/ MANNING AGENCY | K14: TOTAL:
A15: DOLE CARAGA | B15: 45778 | C15: ROBINSONS PLACE, BUTUAN CITY | D15: JENERICK INTERNATIONAL MANPOWER INC. | E15: 1 | F15: =8+6+9+5+1 -> 29 | G15: =2+4+1+5+8 -> 20 | H15: =F15+G15 -> 49 | I15: 1 | K15: =I15+J15 -> 1
D16: PLACEWELL INTERNATIONAL SERVICES CORPORATION | F16: =6+7+7 -> 20 | G16: =4+3+3 -> 10 | H16: =F16+G16 -> 30 | I16: 1 | K16: =I16+J16 -> 1
D17: EXCEL GREEN KARD INTERNATIONAL INC. | F17: =7+5+1 -> 13 | G17: =3+5+6 -> 14 | H17: =F17+G17 -> 27 | I17: 1 | K17: =I17+J17 -> 1
D18: EAST WEST PLACEMENT CENTER INC. | F18: 4 | G18: 3 | H18: =F18+G18 -> 7 | I18: 1 | K18: =I18+J18 -> 1
D19: MMML RECRUITMENT SERVICES INC. | F19: 6 | G19: 2 | H19: =F19+G19 -> 8 | I19: 1 | K19: =I19+J19 -> 1
A20: Sub total: | E20: =SUM(E15:E19) -> 1 | F20: =SUM(F15:F19) -> 72 | G20: =SUM(G15:G19) -> 49 | H20: =SUM(H15:H19) -> 121 | I20: =SUM(I15:I19) -> 5 | J20: =SUM(J15:J19) -> 0 | K20: =SUM(K15:K19) -> 5
A21: PROVINCIAL GOVERNMENT OF DINAGAT ISLANDS THRU THE PROVINCIAL PUBLIC EMPLOYMENT SERVICE OFFICE (PPESO) | B21: May 1-2, 2025 | C21: TABOO AREA, CAPITOL COMPOUND, BRGY. CUARINTA, SAN JOSE, DINAGAT ISLANDS | D21: JENERICK INTERNATIONAL MANPOWER INC. | E21: 1 | F21: 5 | G21: 1 | H21: =F21+G21 -> 6 | I21: 1 | K21: =I21+J21 -> 1
D22: DIMENSION-ALL MANPOWER INC. | F22: 6 | G22: 3 | H22: =F22+G22 -> 9 | I22: 1 | K22: =I22+J22 -> 1
A23: Sub total: | E23: =SUM(E21:E22) -> 1 | F23: =SUM(F21:F22) -> 11 | G23: =SUM(G21:G22) -> 4 | H23: =SUM(H21:H22) -> 15 | I23: =SUM(I21:I22) -> 2 | J23: =SUM(J21:J22) -> 0 | K23: =SUM(K21:K22) -> 2
A24: ST. THERESA COLLEGE INC. IN COORDINATION WITH DOLE-SDSFO | B24: 45793 | C24: ST. THERESA COLLEGE, INC., SURIGAO DEL SUR | D24: 9K INTERNATIONAL MANPOWER & RECRUITMENT SERVICES CORP | E24: 1 | F24: =6+3+2+7+1 -> 19 | G24: =4+7+8+3+4 -> 26 | H24: =F24+G24 -> 45 | I24: 1 | K24: =I24+J24 -> 1
D25: JENERICK INTERNATIONAL MANPOWER INC. | F25: =1+2+8+5 -> 16 | G25: =10+9+8+2+5 -> 34 | H25: =F25+G25 -> 50 | I25: 1 | K25: =I25+J25 -> 1
D26: PLACEWELL INTERNATIONAL SERVICES CORPORATION | F26: 3 | G26: 7 | H26: =F26+G26 -> 10 | I26: 1 | K26: =I26+J26 -> 1
A27: Sub total: | E27: =E24 -> 1 | F27: =SUM(F24:F26) -> 38 | G27: =SUM(G24:G26) -> 67 | H27: =SUM(H24:H26) -> 105 | I27: =SUM(I24:I26) -> 3 | J27: =SUM(J24:J26) -> 0 | K27: =SUM(K24:K26) -> 3
A28: NORTHERN MINDANAO COLLEGES, INC. | B28: 45800 | C28: COLLEGE BUILDING, NORMI, ATEGA STREET, CABADBARAN CITY | D28: JENERICK INTERNATIONAL MANPOWER INC. | E28: 1 | F28: =2+5+8 -> 15 | G28: =7+3+2 -> 12 | H28: =F28+G28 -> 27 | I28: 1 | K28: =I28+J28 -> 1
D29: EAST WEST PLACEMENT CENTER INC. | F29: 0 | G29: 0 | H29: =F29+G29 -> 0 | I29: 1 | K29: =I29+J29 -> 1
A30: Sub total: | E30: =E28 -> 1 | F30: =SUM(F28:F29) -> 15 | G30: =SUM(G28:G29) -> 12 | H30: =SUM(H28:H29) -> 27 | I30: =SUM(I28:I29) -> 2 | J30: =SUM(J28:J29) -> 0 | K30: =SUM(K28:K29) -> 2
A31: NORTH EASTERN MINDANAO STATE UNIVERSITY (NEMSU) IN COORDINATION WITH DOLE-SDSFO | B31: 45804 | C31: NEMSU TANDAG GROUND FLOOR ENGINEERING BUILDING, TANDAG, SURIGAO DEL SUR | D31: PLACEWELL INTERNATIONAL SERVICES CORPORATION | E31: 1 | F31: 6 | G31: 12 | H31: =F31+G31 -> 18 | I31: 1 | K31: =I31+J31 -> 1
D32: 9K INTERNATIONAL MANPOWER & RECRUITMENT SERVICES CORP | F32: =2+6+5+5+3+2 -> 23 | G32: =8+4+5+5+7+4 -> 33 | H32: =F32+G32 -> 56 | I32: 1 | K32: =I32+J32 -> 1
D33: EAST WEST PLACEMENT CENTER INC. | F33: 1 | G33: 6 | H33: =F33+G33 -> 7 | I33: 1 | K33: =I33+J33 -> 1
A34: Sub total: | E34: =E31 -> 1 | F34: =SUM(F31:F33) -> 30 | G34: =SUM(G31:G33) -> 51 | H34: =SUM(H31:H33) -> 81 | I34: =SUM(I31:I33) -> 3 | J34: =SUM(J31:J33) -> 0 | K34: =SUM(K31:K33) -> 3
A35: PUBLIC EMPLOYMENT SERVICE OFFICE RTR | B35: 45805 | C35: NEW RTR PUBLIC TERMINAL, RTR, AGUSAN DEL NORTE | D35: JENERICK INTERNATIONAL MANPOWER INC. | E35: 1 | F35: 2 | G35: 2 | H35: =F35+G35 -> 4 | I35: 1 | K35: =I35+J35 -> 1
D36: PLACEWELL INTERNATIONAL SERVICES CORPORATION | F36: 3 | G36: 3 | H36: =F36+G36 -> 6 | I36: 1 | K36: =I36+J36 -> 1
D37: EAST WEST PLACEMENT CENTER INC. | F37: 2 | G37: 1 | H37: =F37+G37 -> 3 | I37: 1 | K37: =I37+J37 -> 1
A38: Sub total: | E38: =E35 -> 1 | F38: =SUM(F35:F37) -> 7 | G38: =SUM(G35:G37) -> 6 | H38: =SUM(H35:H37) -> 13 | I38: =SUM(I35:I37) -> 3 | J38: =SUM(J35:J37) -> 0 | K38: =SUM(K35:K37) -> 3
A39: GRAND TOTAL: | E39: =E38+E34+E30+E27+E23+E20 -> 6 | F39: =F38+F34+F30+F27+F23+F20 -> 173 | G39: =G38+G34+G30+G27+G23+G20 -> 189 | H39: =H38+H34+H30+H27+H23+H20 -> 362 | I39: =I38+I34+I30+I27+I23+I20 -> 18 | J39: =J38+J34+J30+J27+J23+J20 -> 0 | K39: =K38+K34+K30+K27+K23+K20 -> 18
A41: Prepared by: | E41: Noted by:
A45: AURORA JEAN A. TORRALBA | E45: EDDIE PARAGUYA
A46: Labor and Employment Officer I | E46: Senior Labor and Employment Officer

Sheet JUNE
A10: JOB FAIR REPORT
A11: FOR THE MONTH OF JUNE 2025
A13: ORGANIZER | B13: JOB FAIR DATES | C13: JOB FAIR VENUE | D13: AGENCY | E13: NO. OF JOBS FAIR FACILITATED/ SUPERVISED | F13: NUMBER OF REGISTERED APPLICANTS | I13: NUMBER OF PARTICIPATING AGENCIES
F14: MALE | G14: FEMALE | H14: TOTAL: | I14: LAND BASED RECRUITMENT AGENCY | J14: SEA-BASED/ MANNING AGENCY | K14: TOTAL:
A15: DOLE-SDSFO AND NEMSU TAGBINA | B15: 45812 | C15: NEMSU TAGBINA GYMNASIUM, SURIGAO DEL SUR | D15: PLACEWELL INTERNATIONAL SERVICES CORPORATION | E15: 1 | F15: 5 | G15: 6 | H15: =F15+G15 -> 11 | I15: 1 | K15: =I15+J15 -> 1
D16: ERRX RECRUITMENT CONSULTING INC. | F16: =2+2+7 -> 11 | G16: =8+8+3 -> 19 | H16: =F16+G16 -> 30 | I16: 1 | K16: =I16+J16 -> 1
D17: JENERICK INTERNATIONAL MANPOWER INC. | F17: 3 | G17: 4 | H17: =F17+G17 -> 7 | I17: 1 | K17: =I17+J17 -> 1
A18: Sub total: | E18: =SUM(E15:E17) -> 1 | F18: =SUM(F15:F17) -> 19 | G18: =SUM(G15:G17) -> 29 | H18: =SUM(H15:H17) -> 48 | I18: =SUM(I15:I17) -> 3 | J18: =SUM(J15:J17) -> 0 | K18: =SUM(K15:K17) -> 3
A19: DOLE-SDSFO AND NEMSU LIANGA | B19: 45813 | C19: NEMSU LIANGA, SURIGAO DEL SUR | D19: PLACEWELL INTERNATIONAL SERVICES CORPORATION | E19: 1 | F19: =6+5+4+3 -> 18 | G19: =4+5+6+7 -> 22 | H19: =F19+G19 -> 40 | I19: 1 | K19: =I19+J19 -> 1
A20: Sub total: | E20: =SUM(E19:E19) -> 1 | F20: =F19 -> 18 | G20: =G19 -> 22 | H20: =H19 -> 40 | I20: =SUM(I19:I19) -> 1 | J20: =SUM(J19:J19) -> 0 | K20: =SUM(K19:K19) -> 1
A21: DOLE-SDSFO AND NEMSU CAGWAIT | B21: 45819 | C21: NEMSU CAGWAIT THREE-STOREY BUILDING, SURIGAO DEL SUR | D21: PLACEWELL INTERNATIONAL SERVICES CORPORATION | E21: 1 | F21: 0 | G21: 2 | H21: =F21+G21 -> 2 | I21: 1 | K21: =I21+J21 -> 1
D22: MMML RECRUITMENT SERVICES INC. | F22: 1 | G22: 0 | H22: =F22+G22 -> 1 | I22: 1 | K22: =I22+J22 -> 1
D23: JENERICK INTERNATIONAL MANPOWER INC. | F23: 1 | G23: 4 | H23: =F23+G23 -> 5 | I23: 1 | K23: =I23+J23 -> 1
A24: Sub total: | E24: =E21 -> 1 | F24: =SUM(F21:F23) -> 2 | G24: =SUM(G21:G23) -> 6 | H24: =SUM(H21:H23) -> 8 | I24: =SUM(I21:I23) -> 3 | J24: =SUM(J21:J23) -> 0 | K24: =SUM(K21:K23) -> 3
A25: DOLE-CARAGA | B25: 45820 | C25: ROBINSON'S PLACE, BUTUAN CITY | D25: PLACEWELL INTERNATIONAL SERVICES CORPORATION | E25: 1 | F25: 10 | G25: 4 | H25: =F25+G25 -> 14 | I25: 1 | K25: =I25+J25 -> 1
D26: JENERICK INTERNATIONAL MANPOWER INC. | F26: =6+6+3+3 -> 18 | G26: =4+4+7+2 -> 17 | H26: =F26+G26 -> 35 | I26: 1 | K26: =I26+J26 -> 1
D27: EAST WEST PLACEMENT CENTER INC. | F27: 7 | G27: 13 | H27: =F27+G27 -> 20 | I27: 1 | K27: =I27+J27 -> 1
A28: Sub total: | E28: =E25 -> 1 | F28: =SUM(F25:F27) -> 35 | G28: =SUM(G25:G27) -> 34 | H28: =SUM(H25:H27) -> 69 | I28: =SUM(I25:I27) -> 3 | J28: =SUM(J25:J27) -> 0 | K28: =SUM(K25:K27) -> 3
A29: DOLE-ADSFO AND PROVINCIAL GOVERNMENT OF AGUSAN DEL SUR | B29: JUNE 12-13, 2025 | C29: DATU LIPUS MAKAPONDONG CULTURAL CENTER, GOV. D.O. PLAZA GOVERNMENT CENTER, PROSPERIDAD, AGUSAN DEL SUR | D29: PLACEWELL INTERNATIONAL SERVICES CORPORATION | E29: 1 | F29: =6+3+4+3 -> 16 | G29: =4+7+6+3 -> 20 | H29: =F29+G29 -> 36 | I29: 1 | K29: =I29+J29 -> 1
D30: JENERICK INTERNATIONAL MANPOWER INC. | F30: =2+8 -> 10 | G30: =1+3 -> 4 | H30: =F30+G30 -> 14 | I30: 1 | K30: =I30+J30 -> 1
D31: EAST WEST PLACEMENT CENTER INC. | F31: 0 | G31: 7 | H31: =F31+G31 -> 7 | I31: 1 | K31: =I31+J31 -> 1
D32: MMML RECRUITMENT SERVICES INC. | F32: =2+1 -> 3 | G32: =1+4 -> 5 | H32: =F32+G32 -> 8 | I32: 1 | K32: =I32+J32 -> 1
D33: 9K INTERNATIONAL MANPOWER & RECRUITMENT SERVICES CORP | F33: =6+1+1 -> 8 | G33: =4+9+4 -> 17 | H33: =F33+G33 -> 25 | I33: 1 | K33: =I33+J33 -> 1
A34: Sub total: | E34: =E29 -> 1 | F34: =SUM(F29:F33) -> 37 | G34: =SUM(G29:G33) -> 53 | H34: =SUM(H29:H33) -> 90 | I34: =SUM(I29:I33) -> 5 | J34: =SUM(J29:J33) -> 0 | K34: =SUM(K29:K33) -> 5
A35: DOLE-ADSFO AND PESO- SAN FRANCISCO, AGUSAN DEL SUR | B35: 45827 | C35: GAISANO GRAND MALL, SAN FRANCISCO, AGUSAN DEL SUR | D35: PLACEWELL INTERNATIONAL SERVICES CORPORATION | E35: 1 | F35: 5 | G35: 1 | H35: =F35+G35 -> 6 | I35: 1 | K35: =I35+J35 -> 1
D36: JENERICK INTERNATIONAL MANPOWER INC. | F36: 4 | G36: 2 | H36: =F36+G36 -> 6 | I36: 1 | K36: =I36+J36 -> 1
A37: Sub total: | E37: =E35 -> 1 | F37: =SUM(F35:F36) -> 9 | G37: =SUM(G35:G36) -> 3 | H37: =SUM(H35:H36) -> 12 | I37: =SUM(I35:I36) -> 2 | J37: =SUM(J35:J36) -> 0 | K37: =SUM(K35:K36) -> 2
A38: MPESO-TUBAJON, DINAGAT ISLANDS | B38: JUNE 19-20, 2025 | C38: TAN CHAN MINI GYM, MABINI TUBAJON, DINAGAT ISLANDS | D38: PLACEWELL INTERNATIONAL SERVICES CORPORATION | E38: 1 | F38: 12 | G38: 3 | H38: =F38+G38 -> 15 | I38: 1 | K38: =I38+J38 -> 1
A39: Sub total: | E39: =E38 -> 1 | F39: =F38 -> 12 | G39: =G38 -> 3 | H39: =H38 -> 15 | I39: =SUM(I38:I38) -> 1 | J39: =SUM(J38:J38) -> 0 | K39: =SUM(K38:K38) -> 1
A40: DOLE-ADSO AND PESO-BUNAWAN, AGUSAN DEL SUR | B40: 45829 | C40: SAN TEODORO GYMNASIUM, BUNAWAN, AGUSAN DEL SUR | D40: ERRX RECRUITMENT CONSULTING INC. | E40: 1 | F40: 4 | G40: 10 | H40: =F40+G40 -> 14 | I40: 1 | K40: =I40+J40 -> 1
D41: DIMENSION-ALL MANPOWER INC. | F41: 1 | G41: 5 | H41: =F41+G41 -> 6 | I41: 1 | K41: =I41+J41 -> 1
D42: PLACEWELL INTERNATIONAL SERVICES CORPORATION | F42: 0 | G42: 0 | H42: =F42+G42 -> 0 | I42: 1 | K42: =I42+J42 -> 1
A43: Sub total: | E43: =E40 -> 1 | F43: =SUM(F40:F42) -> 5 | G43: =SUM(G40:G42) -> 15 | H43: =SUM(H40:H42) -> 20 | I43: =SUM(I40:I42) -> 3 | J43: =SUM(J40:J42) -> 0 | K43: =SUM(K40:K42) -> 3
A44: DOLE-ADSFO AND PESO- BAYUGAN CITY | B44: 45831 | C44: LOPE A. ASIS GYM, BAYUGAN CITY | D44: JENERICK INTERNATIONAL MANPOWER INC. | E44: 1 | F44: =4+4+5+9 -> 22 | G44: =3+1+5+1 -> 10 | H44: =F44+G44 -> 32 | I44: 1 | K44: =I44+J44 -> 1
D45: MMML RECRUITMENT SERVICES INC. | F45: =3+7+2+2 -> 14 | G45: =7+3+6+1 -> 17 | H45: =F45+G45 -> 31 | I45: 1 | K45: =I45+J45 -> 1
D46: PLACEWELL INTERNATIONAL SERVICES CORPORATION | F46: =7+5+3 -> 15 | G46: =1+5+7 -> 13 | H46: =F46+G46 -> 28 | I46: 1 | K46: =I46+J46 -> 1
D47: SIM-SOH INTERNATIONAL SERVICES INC. | F47: 0 | G47: 0 | H47: =F47+G47 -> 0 | I47: 1 | K47: =I47+J47 -> 1
A48: Sub total: | E48: =E44 -> 1 | F48: =SUM(F44:F47) -> 51 | G48: =SUM(G44:G47) -> 40 | H48: =SUM(H44:H47) -> 91 | I48: =SUM(I44:I47) -> 4 | J48: =SUM(J44:J47) -> 0 | K48: =SUM(K44:K47) -> 4
A49: GRAND TOTAL: | E49: =E48+E43+E39+E37+E34+E28+E24+E20+E18 -> 9 | F49: =F48+F43+F39+F37+F34+F28+F24+F20+F18 -> 188 | G49: =G48+G43+G39+G37+G34+G28+G24+G20+G18 -> 205 | H49: =H48+H43+H39+H37+H34+H28+H24+H20+H18 -> 393 | I49: =I48+I43+I39+I37+I34+I28+I24+I20+I18 -> 25 | J49: =J48+J43+J39+J37+J34+J28+J24+J20+J18 -> 0 | K49: =K48+K43+K39+K37+K34+K28+K24+K20+K18 -> 25
A51: Prepared by: | E51: Noted by:
...

Sheet JULY
A10: JOB FAIR REPORT
A11: FOR THE MONTH OF JULY 2025
A13: ORGANIZER | B13: JOB FAIR DATES | C13: JOB FAIR VENUE | D13: AGENCY | E13: NO. OF JOBS FAIR FACILITATED/ SUPERVISED | F13: NUMBER OF REGISTERED APPLICANTS | I13: NUMBER OF PARTICIPATING AGENCIES | L13: REMARKS
F14: MALE | G14: FEMALE | H14: TOTAL: | I14: LAND BASED RECRUITMENT AGENCY | J14: SEA-BASED/ MANNING AGENCY | K14: TOTAL:
A15: LGU JABONGA AGUSAN DEL NORTE | B15: 45839 | C15: MUNICIPAL LOBBY, JABONGA, AGUSAN DEL NORTE | D15: PLACEWELL INTERNATIONAL SERVICES CORPORATION | E15: 1 | F15: 6 | G15: 1 | H15: =F15+G15 -> 7 | I15: 1 | K15: =I15+J15 -> 1
A16: Sub total: | E16: =SUM(E15:E15) -> 1 | F16: =SUM(F15:F15) -> 6 | G16: =SUM(G15:G15) -> 1 | H16: =SUM(H15:H15) -> 7 | I16: =SUM(I15:I15) -> 1 | J16: =SUM(J15:J15) -> 0 | K16: =SUM(K15:K15) -> 1
A17: MPESO CARMEN AGUSAN DEL NORTE | B17: 45846 | C17: MUNICIPAL GYM, CARMEN, AGUSAN DEL NORTE | D17: PLACEWELL INTERNATIONAL SERVICES CORPORATION | E17: 1 | F17: 2 | G17: 1 | H17: =F17+G17 -> 3 | I17: 1 | K17: =I17+J17 -> 1
D18: JENERICK INTERNATIONAL MANPOWER INC. | F18: 2 | G18: 2 | H18: =F18+G18 -> 4 | I18: 1 | K18: =I18+J18 -> 1
A19: Sub total: | E19: =SUM(E17:E17) -> 1 | F19: =SUM(F17:F18) -> 4 | G19: =SUM(G17:G18) -> 3 | H19: =SUM(H17:H18) -> 7 | I19: =SUM(I17:I18) -> 2 | J19: =SUM(J17:J18) -> 0 | K19: =SUM(K17:K18) -> 2
A20: MPESO BUENAVISTA, AGUSAN DEL NORTE | B20: 45860 | C20: MUNICIPAL GYMNASIUM, AGUSAN DEL NORTE | D20: PLACEWELL INTERNATIONAL SERVICES CORPORATION | E20: 1 | F20: 17 | G20: 5 | H20: =F20+G20 -> 22 | I20: 1 | K20: =I20+J20 -> 1
D21: JENERICK INTERNATIONAL MANPOWER INC. | F21: 27 | G21: 14 | H21: =F21+G21 -> 41 | I21: 1 | K21: =I21+J21 -> 1
A22: Sub total: | E22: =E20 -> 1 | F22: =SUM(F20:F21) -> 44 | G22: =SUM(G20:G21) -> 19 | H22: =SUM(H20:H21) -> 63 | I22: =SUM(I20:I21) -> 2 | J22: =SUM(J20:J21) -> 0 | K22: =SUM(K20:K21) -> 2
A23: PESO CABADBARAN CITY | B23: 45868 | C23: CITY SOCIAL HALL, PEOPLES GOVERNMENT CENTER, CABADBARAN CITY | D23: DIMENSION-ALL MANPOWER INC. | E23: 1 | F23: 0 | G23: 2 | H23: =F23+G23 -> 2 | I23: 1 | K23: =I23+J23 -> 1
D24: PLACEWELL INTERNATIONAL SERVICES CORPORATION | F24: 2 | G24: 7 | H24: =F24+G24 -> 9 | I24: 1 | K24: =I24+J24 -> 1
D25: JENERICK INTERNATIONAL MANPOWER INC. | F25: 2 | G25: 2 | H25: =F25+G25 -> 4 | I25: 1 | K25: =I25+J25 -> 1
D26: EAST WEST PLACEMENT CENTER INC. | F26: 8 | G26: 12 | H26: =F26+G26 -> 20 | I26: 1 | K26: =I26+J26 -> 1
A27: Sub total: | E27: =E23 -> 1 | F27: =SUM(F23:F26) -> 12 | G27: =SUM(G23:G26) -> 23 | H27: =SUM(H23:H26) -> 35 | I27: =SUM(I23:I26) -> 4 | J27: =SUM(J23:J26) -> 0 | K27: =SUM(K23:K26) -> 4
A28: GRAND TOTAL: | E28: =E27+E22+E19+E16 -> 4 | F28: =F27+F22+F19+F16 -> 66 | G28: =G27+G22+G19+G16 -> 46 | H28: =H27+H22+H19+H16 -> 112 | I28: =I27+I22+I19+I16 -> 9 | J28: =J27+J22+J19+J16 -> 0 | K28: =K27+K22+K19+K16 -> 9
A30: Prepared by: | E30: Noted by:
A34: AURORA JEAN A. TORRALBA | E34: MARISSA A. GARAY
A35: Labor and Employment Officer I | E35: Supervising Labor and Employment Officer

Sheet AUG
A10: JOB FAIR REPORT
A11: FOR THE MONTH OF AUGUST 2025
A13: ORGANIZER | B13: JOB FAIR DATES | C13: JOB FAIR VENUE | D13: AGENCY | E13: NO. OF JOBS FAIR FACILITATED/ SUPERVISED | F13: NUMBER OF REGISTERED APPLICANTS | I13: NUMBER OF PARTICIPATING AGENCIES | L13: REMARKS
F14: MALE | G14: FEMALE | H14: TOTAL: | I14: LAND BASED RECRUITMENT AGENCY | J14: SEA-BASED/ MANNING AGENCY | K14: TOTAL:
A15: MPESO LINGIG, SURIGAO DEL SUR AND DOLE-SDSFO | B15: 45870 | C15: MRRM OFFICE, LINGIG, SURIGAO DEL SUR | D15: PLACEWELL INTERNATIONAL SERVICES CORPORATION | E15: 1 | F15: 2 | G15: 1 | H15: =F15+G15 -> 3 | I15: 1 | K15: =I15+J15 -> 1
A16: Sub total: | E16: =SUM(E15:E15) -> 1 | F16: =SUM(F15:F15) -> 2 | G16: =SUM(G15:G15) -> 1 | H16: =SUM(H15:H15) -> 3 | I16: =SUM(I15:I15) -> 1 | J16: =SUM(J15:J15) -> 0 | K16: =SUM(K15:K15) -> 1
A17: LGU BUTUAN | B17: 45883 | C17: 3RD FLOOR, EVENTS CENTER, SM BUTUAN, J.C. AQUINO AVE., BUTUAN CITY | D17: MMML RECRUITMENT SERVICES INC. | E17: 1 | F17: 3 | G17: 15 | H17: =F17+G17 -> 18 | I17: 1 | K17: =I17+J17 -> 1
D18: AL-ALAMIA INTERNATIONAL MANPOWER SERVICES | F18: 3 | G18: 11 | H18: =F18+G18 -> 14 | I18: 1 | K18: =I18+J18 -> 1
D19: 9K INTERNATIONAL MANPOWER & RECRUITMENT SERVICES CORP. | F19: 22 | G19: 28 | H19: =F19+G19 -> 50 | I19: 1 | K19: =I19+J19 -> 1
D20: EAST WEST PLACEMENT CENTER INC. | F20: 23 | G20: 16 | H20: =F20+G20 -> 39 | I20: 1 | K20: =I20+J20 -> 1
D21: JENERICK INTERNATIONAL MANPOWER INC. | F21: 0 | G21: 15 | H21: =F21+G21 -> 15 | I21: 1 | K21: =I21+J21 -> 1
D22: PLACEWELL INTERNATIONAL SERVICES CORP. | F22: 11 | G22: 9 | H22: =F22+G22 -> 20 | I22: 1 | K22: =I22+J22 -> 1
A23: Sub total: | E23: =SUM(E17:E17) -> 1 | F23: =SUM(F17:F22) -> 62 | G23: =SUM(G17:G22) -> 94 | H23: =SUM(H17:H22) -> 156 | I23: =SUM(I17:I22) -> 6 | J23: =SUM(J17:J22) -> 0 | K23: =SUM(K17:K22) -> 6
A24: RMN DXBC/ IFM | B24: 45884 | C24: 3RD FLOOR, EVENTS CENTER, SM BUTUAN, J.C. AQUINO AVE., BUTUAN CITY | D24: MMML RECRUITMENT SERVICES INC. | E24: 1 | F24: 3 | G24: 2 | H24: =F24+G24 -> 5 | I24: 1 | K24: =I24+J24 -> 1
D25: AL-ALAMIA INTERNATIONAL MANPOWER SERVICES | F25: 0 | G25: 5 | H25: =F25+G25 -> 5 | I25: 1 | K25: =I25+J25 -> 1
D26: EAST WEST PLACEMENT CENTER INC. | F26: 1 | G26: 4 | H26: =F26+G26 -> 5 | I26: 1 | K26: =I26+J26 -> 1
D27: JENERICK INTERNATIONAL MANPOWER INC. | F27: 4 | G27: 2 | H27: =F27+G27 -> 6 | I27: 1 | K27: =I27+J27 -> 1
D28: PLACEWELL INTERNATIONAL SERVICES CORP. | F28: 5 | G28: 2 | H28: =F28+G28 -> 7 | I28: 1 | K28: =I28+J28 -> 1
A29: Sub total: | E29: =E24 -> 1 | F29: =SUM(F24:F28) -> 13 | G29: =SUM(G24:G28) -> 15 | H29: =SUM(H24:H28) -> 28 | I29: =SUM(I24:I28) -> 5 | J29: =SUM(J24:J28) -> 0 | K29: =SUM(K24:K28) -> 5
A30: DOLE-SDSFO | B30: 45709 | C30: MUNICIPAL PLAZA, HINATUAN, SURIGAO DEL SUR | D30: MMML RECRUITMENT SERVICES INC. | E30: 1 | F30: 3 | G30: 5 | H30: =F30+G30 -> 8 | I30: 1 | K30: =I30+J30 -> 1
D31: AL-ALAMIA INTERNATIONAL MANPOWER SERVICES | F31: 1 | G31: 5 | H31: =F31+G31 -> 6 | I31: 1 | K31: =I31+J31 -> 1
D32: EAST WEST PLACEMENT CENTER INC. | F32: 5 | G32: 6 | H32: =F32+G32 -> 11 | I32: 1 | K32: =I32+J32 -> 1
D33: PLACEWELL INTERNATIONAL SERVICES CORP. | F33: 4 | G33: 9 | H33: =F33+G33 -> 13 | I33: 1 | K33: =I33+J33 -> 1
A34: Sub total: | E34: =E30 -> 1 | F34: =SUM(F30:F33) -> 13 | G34: =SUM(G30:G33) -> 25 | H34: =SUM(H30:H33) -> 38 | I34: =SUM(I30:I33) -> 4 | J34: =SUM(J30:J33) -> 0 | K34: =SUM(K30:K33) -> 4
A35: GRAND TOTAL: | E35: =E34+E29+E23+E16 -> 4 | F35: =F34+F29+F23+F16 -> 90 | G35: =G34+G29+G23+G16 -> 135 | H35: =H34+H29+H23+H16 -> 225 | I35: =I34+I29+I23+I16 -> 16 | J35: =J34+J29+J23+J16 -> 0 | K35: =K34+K29+K23+K16 -> 16
A37: Prepared by: | E37: Noted by:
A41: AURORA JEAN A. TORRALBA | E41: MARISSA A. GARAY
A42: Labor and Employment Officer I | E42: Supervising Labor and Employment Officer

Sheet SEP
A10: JOB FAIR REPORT
A11: FOR THE MONTH OF SEPTEMBER 2025
A13: ORGANIZER | B13: JOB FAIR DATES | C13: JOB FAIR VENUE | D13: AGENCY | E13: NO. OF JOBS FAIR FACILITATED/ SUPERVISED | F13: NUMBER OF REGISTERED APPLICANTS | I13: NUMBER OF PARTICIPATING AGENCIES | L13: REMARKS
F14: MALE | G14: FEMALE | H14: TOTAL: | I14: LAND BASED RECRUITMENT AGENCY | J14: SEA-BASED/ MANNING AGENCY | K14: TOTAL:
A15: LOCAL GOVERNMENT UNIT OF BISLIG | B15: 45909 | C15: Bislig City Cultural and Sports Center, Bislig City, Surigao del Sur | D15: MMML RECRUITMENT SERVICES INC. | E15: 1 | F15: 2 | G15: 5 | H15: =F15+G15 -> 7 | I15: 1 | K15: =I15+J15 -> 1
D16: AL-ALAMIA INTERNATIONAL MANPOWER SERVICES | F16: 1 | G16: 5 | H16: =F16+G16 -> 6 | I16: 1 | K16: =I16+J16 -> 1
D17: EXCEL GREEN KARD INTERNATIONAL INC. | F17: 9 | G17: 6 | H17: =F17+G17 -> 15 | I17: 1 | K17: =I17+J17 -> 1
D18: ERRX RECRUITMENT CONSULTING INC. | F18: =4+6+1 -> 11 | G18: =6+4+2 -> 12 | H18: =F18+G18 -> 23 | I18: 1 | K18: =I18+J18 -> 1
A19: Sub total: | E19: =SUM(E15:E15) -> 1 | F19: =SUM(F15:F18) -> 23 | G19: =SUM(G15:G18) -> 28 | H19: =SUM(H15:H18) -> 51 | I19: =SUM(I15:I18) -> 4 | J19: =SUM(J15:J18) -> 0 | K19: =SUM(K15:K18) -> 4
A20: MUNICIPALITY OF MADRID, SURIGAO DEL SUR | B20: 45910 | C20: LGU-Madrid, Convention Center, Madrid, Surigao del Sur | D20: AL-ALAMIA INTERNATIONAL MANPOWER SERVICES | E20: 1 | F20: 0 | G20: 0 | H20: =F20+G20 -> 0 | I20: 1 | K20: =I20+J20 -> 1
D21: 9K INTERNATIONAL MANPOWER & RECRUITMENT SERVICES CORP. | F21: 4 | G21: 4 | H21: =F21+G21 -> 8 | I21: 1 | K21: =I21+J21 -> 1
D22: EAST WEST PLACEMENT CENTER INC. | F22: 5 | G22: 8 | H22: =F22+G22 -> 13 | I22: 1 | K22: =I22+J22 -> 1
D23: MMML RECRUITMENT SERVICES INC. | F23: 2 | G23: 4 | H23: =F23+G23 -> 6 | I23: 1 | K23: =I23+J23 -> 1
A24: Sub total: | E24: =SUM(E20:E20) -> 1 | F24: =SUM(F20:F23) -> 11 | G24: =SUM(G20:G23) -> 16 | H24: =SUM(H20:H23) -> 27 | I24: =SUM(I20:I23) -> 4 | J24: =SUM(J20:J23) -> 0 | K24: =SUM(K20:K23) -> 4
A25: TESDA-CARAGA | B25: 45912 | C25: Robinsons Mall, J.C. Aquino Ave., Butuan City | D25: AL-ALAMIA INTERNATIONAL MANPOWER SERVICES | E25: 1 | F25: 0 | G25: 6 | H25: =F25+G25 -> 6 | I25: 1 | K25: =I25+J25 -> 1
D26: MMML RECRUITMENT SERVICES INC. | F26: 4 | G26: 13 | H26: =F26+G26 -> 17 | I26: 1 | K26: =I26+J26 -> 1
D27: DIMENSION-ALL MANPOWER INC. | F27: 3 | G27: 2 | H27: =F27+G27 -> 5 | I27: 1 | K27: =I27+J27 -> 1
D28: EAST WEST PLACEMENT CENTER INC. | F28: 7 | G28: 10 | H28: =F28+G28 -> 17 | I28: 1 | K28: =I28+J28 -> 1
D29: JENERICK INTERNATIONAL MANPOWER INC. | F29: 10 | G29: 8 | H29: =F29+G29 -> 18 | I29: 1 | K29: =I29+J29 -> 1
A30: Sub total: | E30: =E25 -> 1 | F30: =SUM(F25:F29) -> 24 | G30: =SUM(G25:G29) -> 39 | H30: =SUM(H25:H29) -> 63 | I30: =SUM(I25:I29) -> 5 | J30: =SUM(J25:J29) -> 0 | K30: =SUM(K25:K29) -> 5
A31: TESDA-CARAGA | B31: 45913 | C31: Naliyagan Ground, GDOP, Government Center, Patin-ay, Prosperidad, Agusan del Sur | D31: MMML RECRUITMENT SERVICES INC. | E31: 1 | F31: 1 | G31: 7 | H31: =F31+G31 -> 8 | I31: 1 | K31: =I31+J31 -> 1
A32: Sub total: | E32: =E31 -> 1 | F32: =SUM(F31:F31) -> 1 | G32: =SUM(G31:G31) -> 7 | H32: =SUM(H31:H31) -> 8 | I32: =SUM(I31:I31) -> 1 | J32: =SUM(J31:J31) -> 0 | K32: =SUM(K31:K31) -> 1
A33: DOLE-CARAGA | B33: 45913 | C33: Robinsons Mall, J.C. Aquino Ave., Butuan City | D33: JENERICK INTERNATIONAL MANPOWER INC. | E33: 1 | F33: =8+3+3 -> 14 | G33: =2+7+1 -> 10 | H33: =F33+G33 -> 24 | I33: 1 | K33: =I33+J33 -> 1
D34: AL-ALAMIA INTERNATIONAL MANPOWER SERVICES | F34: 1 | G34: 8 | H34: =F34+G34 -> 9 | I34: 1 | K34: =I34+J34 -> 1
D35: EAST WEST PLACEMENT CENTER INC. | F35: =6+5 -> 11 | G35: 9 | H35: =F35+G35 -> 20 | I35: 1 | K35: =I35+J35 -> 1
A36: Sub total: | E36: =E33 -> 1 | F36: =SUM(F33:F35) -> 26 | G36: =SUM(G33:G35) -> 27 | H36: =SUM(H33:H35) -> 53 | I36: =SUM(I33:I35) -> 3 | J36: =SUM(J33:J35) -> 0 | K36: =SUM(K33:K35) -> 3
A37: LOCAL GOVERNMENT UNIT OF SURIGAO | B37: 45913 | C37: City Cultural Center, Surigao City | D37: SMC MANPOWER AGENCY PHILIPPINES COMPANY | E37: 1 | F37: 15 | G37: 12 | H37: =F37+G37 -> 27 | I37: 1 | K37: =I37+J37 -> 1
A38: Sub total: | E38: =E37 -> 1 | F38: =F37 -> 15 | G38: =G37 -> 12 | H38: =H37 -> 27 | I38: =I37 -> 1 | J38: =J37 -> 0 | K38: =K37 -> 1
A39: DOLE-PDIFO | B39: 45913 | C39: Barangay Gym, Mahayahay, San Jose, Dinagat Islands | D39: DIMENSION-ALL MANPOWER INC. | E39: 1 | F39: 0 | G39: 3 | H39: =F39+G39 -> 3 | I39: 1 | K39: =I39+J39 -> 1
D40: SMC MANPOWER AGENCY PHILIPPINES COMPANY | F40: 1 | G40: 3 | H40: =F40+G40 -> 4 | I40: 1 | K40: =I40+J40 -> 1
A41: Sub total: | E41: =E39 -> 1 | F41: =SUM(F39:F40) -> 1 | G41: =SUM(G39:G40) -> 6 | H41: =SUM(H39:H40) -> 7 | I41: =SUM(I39:I40) -> 2 | J41: =SUM(J39:J40) -> 0 | K41: =SUM(K39:K40) -> 2
A42: MUNICIPALITY OF ESPERANZA, AGUSAN DEL SUR | B42: 45925 | C42: Datu Mankumbate Deo S. Manpalitan, Sr. Events and Cultural Center (Covered Court), Poblacion, Esperanza, Agusan del Sur | D42: EAST WEST PLACEMENT CENTER INC. | E42: 1 | F42: =7+1 -> 8 | G42: =4+3 -> 7 | H42: =F42+G42 -> 15 | I42: 1 | K42: =I42+J42 -> 1
D43: SIM-SOH INTERNATIONAL SERVICES INC | F43: 0 | G43: 0 | H43: =F43+G43 -> 0 | I43: 1 | K43: =I43+J43 -> 1
D44: AL-ALAMIA INTERNATIONAL MANPOWER SERVICES | F44: 0 | G44: 8 | H44: =F44+G44 -> 8 | I44: 1 | K44: =I44+J44 -> 1
A45: Sub total: | E45: =E42 -> 1 | F45: =SUM(F42:F44) -> 8 | G45: =SUM(G42:G44) -> 15 | H45: =SUM(H42:H44) -> 23 | I45: =SUM(I42:I44) -> 3 | J45: =SUM(J42:J44) -> 0 | K45: =SUM(K42:K44) -> 3
A46: MUNICIPALITY OF TRENTO, AGUSAN DEL SUR | B46: 45926 | C46: D.O. Plaza Park, Poblacion, Trento, Agusan del Sur | D46: AL-ALAMIA INTERNATIONAL MANPOWER SERVICES | E46: 1 | F46: 6 | G46: 5 | H46: =F46+G46 -> 11 | I46: 1 | K46: =I46+J46 -> 1
D47: SMC MANPOWER AGENCY PHILIPPINES COMPANY | F47: 1 | G47: 0 | H47: =F47+G47 -> 1 | I47: 1 | K47: =I47+J47 -> 1
A48: Sub total: | E48: =E46 -> 1 | F48: =SUM(F46:F47) -> 7 | G48: =SUM(G46:G47) -> 5 | H48: =SUM(H46:H47) -> 12 | I48: =SUM(I46:I47) -> 2 | J48: =SUM(J46:J47) -> 0 | K48: =SUM(K46:K47) -> 2
A49: MUNICIPALITY OF SAN MIGUEL, SURIGAO DEL SUR | B49: 45927 | C49: Poblacion Gymnasium, Poblacion, San Miguel, Surigao del Sur | D49: AL-ALAMIA INTERNATIONAL MANPOWER SERVICES | E49: 1 | F49: 1 | G49: 6 | H49: =F49+G49 -> 7 | I49: 1 | K49: =I49+J49 -> 1
A50: Sub total: | E50: =E49 -> 1 | F50: =F49 -> 1 | G50: =G49 -> 6 | H50: =H49 -> 7 | I50: =I49 -> 1 | J50: =J49 -> 0 | K50: =K49 -> 1
...

Sheet OCT
A10: JOB FAIR REPORT
A11: FOR THE MONTH OF OCTOBER 2025
A13: ORGANIZER | B13: JOB FAIR DATES | C13: JOB FAIR VENUE | D13: AGENCY | E13: NO. OF JOBS FAIR FACILITATED/ SUPERVISED | F13: NUMBER OF REGISTERED APPLICANTS | I13: NUMBER OF PARTICIPATING AGENCIES | L13: REMARKS
F14: MALE | G14: FEMALE | H14: TOTAL: | I14: LAND BASED RECRUITMENT AGENCY | J14: SEA-BASED/ MANNING AGENCY | K14: TOTAL:
A15: NATIONAL HOUSING AUTHORITY | B15: 45932 | C15: Capitol Covered Court, Butuan City | D15: EAST WEST PLACEMENT CENTER INC. | E15: 1 | F15: 3 | G15: 1 | H15: =F15+G15 -> 4 | I15: 1 | K15: =I15+J15 -> 1
A16: Sub total: | E16: =SUM(E15:E15) -> 1 | F16: =SUM(F15:F15) -> 3 | G16: =SUM(G15:G15) -> 1 | H16: =SUM(H15:H15) -> 4 | I16: =SUM(I15:I15) -> 1 | J16: =SUM(J15:J15) -> 0 | K16: =SUM(K15:K15) -> 1
A17: PESO-BARABO, SURIGAO DEL SUR AND DOLE-SDSFO | B17: 45950 | C17: Municipal Gymnasium, Barobo, Surigao del Sur | D17: MMML RECRUITMENT SERVICES INC. | E17: 1 | F17: 3 | G17: 3 | H17: =F17+G17 -> 6 | I17: 1 | K17: =I17+J17 -> 1
D18: PLACEWELL INTERNATIONAL SERVICES CORP. | F18: 2 | G18: 7 | H18: =F18+G18 -> 9 | I18: 1 | K18: =I18+J18 -> 1
A19: Sub total: | E19: =SUM(E17:E17) -> 1 | F19: =SUM(F17:F18) -> 5 | G19: =SUM(G17:G18) -> 10 | H19: =SUM(H17:H18) -> 15 | I19: =SUM(I17:I18) -> 2 | J19: =SUM(J17:J18) -> 0 | K19: =SUM(K17:K18) -> 2
A20: GRAND TOTAL: | E20: =E16+E19 -> 2 | F20: =F16+F19 -> 8 | G20: =G16+G19 -> 11 | H20: =H16+H19 -> 19 | I20: =I16+I19 -> 3 | J20: =J16+J19 -> 0 | K20: =K16+K19 -> 3
A22: Prepared by: | E22: Noted by:
A26: AURORA JEAN A. TORRALBA | E26: MARISSA A. GARAY
A27: Labor and Employment Officer I | E27: Supervising Labor and Employment Officer

Sheet NOV
A10: JOB FAIR REPORT
A11: FOR THE MONTH OF NOVEMBER 2025
A13: ORGANIZER | B13: JOB FAIR DATES | C13: JOB FAIR VENUE | D13: AGENCY | E13: NO. OF JOBS FAIR FACILITATED/ SUPERVISED | F13: NUMBER OF REGISTERED APPLICANTS | I13: NUMBER OF PARTICIPATING AGENCIES | L13: REMARKS
F14: MALE | G14: FEMALE | H14: TOTAL: | I14: LAND BASED RECRUITMENT AGENCY | J14: SEA-BASED/ MANNING AGENCY | K14: TOTAL:
A15: MUNICIPALITY OF BUENAVISTA, AGUSAN DEL NORTE | B15: 45980 | C15: Municipal Gymnasium, Buenavista, Agusan del Norte | D15: JENERICK INTERNATIONAL MANPOWER INC. | E15: 1 | F15: 8 | G15: 7 | H15: =F15+G15 -> 15 | I15: 1 | K15: =I15+J15 -> 1
D16: EAST WEST PLACEMENT CENTER INC. | F16: 7 | G16: 8 | H16: =F16+G16 -> 15 | I16: 1 | K16: =I16+J16 -> 1
D17: PLACEWELL INTERNATIONAL SERVICES CORP. | F17: 10 | G17: 5 | H17: =F17+G17 -> 15 | I17: 1 | K17: =I17+J17 -> 1
D18: RITE MERIT INTERNATIONAL | F18: 14 | G18: 5 | H18: =F18+G18 -> 19 | I18: 1 | K18: =I18+J18 -> 1
A19: Sub total: | E19: =E15 -> 1 | F19: =SUM(F15:F18) -> 39 | G19: =SUM(G15:G18) -> 25 | H19: =SUM(H15:H18) -> 64 | I19: =SUM(I15:I18) -> 4 | J19: =SUM(J15:J18) -> 0 | K19: =SUM(K15:K18) -> 4
A20: GRAND TOTAL: | E20: =E19 -> 1 | F20: =F19 -> 39 | G20: =G19 -> 25 | H20: =H19 -> 64 | I20: =I19 -> 4 | J20: =J19 -> 0 | K20: =K19 -> 4
A22: Prepared by: | E22: Noted by:
A26: AURORA JEAN A. TORRALBA | E26: MARISSA A. GARAY
A27: Labor and Employment Officer I | E27: Supervising Labor and Employment Officer

Sheet DEC
A10: JOB FAIR REPORT
A11: FOR THE MONTH OF DECEMBER 2025
A13: ORGANIZER | B13: JOB FAIR DATES | C13: JOB FAIR VENUE | D13: AGENCY | E13: NO. OF JOBS FAIR FACILITATED/ SUPERVISED | F13: NUMBER OF REGISTERED APPLICANTS | I13: NUMBER OF PARTICIPATING AGENCIES | L13: REMARKS
F14: MALE | G14: FEMALE | H14: TOTAL: | I14: LAND BASED RECRUITMENT AGENCY | J14: SEA-BASED/ MANNING AGENCY | K14: TOTAL:
A15: DOLE-CARAGA | B15: 45992 | C15: Robinsons Mall, JC Aquino Ave., Butuan City | D15: JENERICK INTERNATIONAL MANPOWER INC. | E15: 1 | F15: 8 | G15: 13 | H15: =F15+G15 -> 21 | I15: 1 | K15: =I15+J15 -> 1
D16: EAST WEST PLACEMENT CENTER INC. | F16: 5 | G16: 4 | H16: =F16+G16 -> 9 | I16: 1 | K16: =I16+J16 -> 1
D17: PLACEWELL INTERNATIONAL SERVICES CORP. | F17: 5 | G17: 5 | H17: =F17+G17 -> 10 | I17: 1 | K17: =I17+J17 -> 1
A18: Sub total: | E18: =E15 -> 1 | F18: =SUM(F15:F17) -> 18 | G18: =SUM(G15:G17) -> 22 | H18: =SUM(H15:H17) -> 40 | I18: =SUM(I15:I17) -> 3 | J18: =SUM(J15:J17) -> 0 | K18: =SUM(K15:K17) -> 3
A19: DOLE-SDSFO | B19: 45993 | C19: Municipal Gymnasium, Tago, Surigao del Sur | D19: MMML RECRUITMENT SERVICES INC. | E19: 1 | F19: 0 | G19: 1 | H19: =F19+G19 -> 1 | I19: 1 | K19: =I19+J19 -> 1
D20: 9K INTERNATIONAL MANPOWER & RECRUITMENT SERVICES CORP. | F20: 1 | G20: 2 | H20: =F20+G20 -> 3 | I20: 1 | K20: =I20+J20 -> 1
A21: Sub total: | E21: =E19 -> 1 | F21: =SUM(F19:F20) -> 1 | G21: =SUM(G19:G20) -> 3 | H21: =SUM(H19:H20) -> 4 | I21: =SUM(I19:I20) -> 2 | J21: =SUM(J19:J20) -> 0 | K21: =SUM(K19:K20) -> 2
A22: GRAND TOTAL: | E22: =E18+E21 -> 2 | F22: =F18+F21 -> 19 | G22: =G18+G21 -> 25 | H22: =H18+H21 -> 44 | I22: =I18+I21 -> 5 | J22: =J18+J21 -> 0 | K22: =K18+K21 -> 5
A24: Prepared by: | E24: Noted by:
A28: AURORA JEAN A. TORRALBA | E28: MARISSA A. GARAY
A29: Labor and Employment Officer I | E29: Supervising Labor and Employment Officer
